Workbook

Sheet PLAN DE CUENTAS NUEVO
A1: Codigo | B1: Nombre de cuenta | C1: Imput | D1: Resultado? | E1: Tipo Sub Cta | F1: Moneda | H1: Nivel
A2: 1 | B2: ACTIVO | H2: 1
A3: 1.01 | B3: DISPONIBILIDADES | H3: 2
A4: 1.01.01 | B4: CAJAS | H4: 3
A5: 1.01.01.001 | B5: Caja | C5: 1 | D5: N | H5: 4
A6: 1.01.01.002 | B6: Caja M. Extr. U$S | C6: 2 | D6: N | F6: 2 | H6: 4
A7: 1.01.01.003 | B7: Fondo Fijo | C7: 3 | D7: N | H7: 4
A8: 1.01.01.004 | B8: Caja Central | C8: 152 | D8: N | H8: 4
A9: 1.01.01.005 | B9: Caja de seg.efect.-Bco.Rio Maipú | C9: 1974 | D9: N | H9: 4
A10: 1.01.01.006 | B10: Caja Seg-U$S-Nro 48-Bco Santander-WCL | C10: 2124 | D10: N | F10: 2 | H10: 4
A11: 1.01.01.007 | B11: Diferencia de Caja | C11: 1736 | D11: N | H11: 4
A12: 1.01.01.008 | B12: Diferencia Moneda Extranjera | C12: 1740 | D12: N | F12: 2 | H12: 4
A13: 1.01.01.009 | B13: Caja Compensación | C13: 3600 | D13: N | H13: 4
A14: 1.01.01.010 | B14: Caja Fiduciario Fid.San Pablo Este | C14: 3844 | D14: N | H14: 4
A15: 1.01.01.011 | B15: Caja Administración | C15: 3870 | D15: N | H15: 4
A16: 1.01.01.012 | B16: Caja Seg U$S-Nro 4-Bco Francés-Torres SP SRL | C16: 3874 | D16: N | F16: 2 | H16: 4
A17: 1.01.01.013 | B17: Caja M. Extr. Euros | C17: 2122 | D17: N | F17: 3 | H17: 4
A18: 1.01.02 | B18: BANCOS | H18: 3
A19: 1.01.02.001 | B19: Bancos Cta Cte | C19: 4 | D19: N | E19: 3 | H19: 4
A20: 1.01.02.002 | B20: Bancos Cajas de Ahorro | C20: 5 | D20: N | E20: 3 | H20: 4
A21: 1.01.02.003 | B21: Banco cta cte U$S | C21: 3607 | D21: N | E21: 3 | F21: 2 | H21: 4
A22: 1.02 | B22: INVERSIONES | H22: 2
A23: 1.02.01 | B23: INVERSIONES TEMPORARIAS | H23: 3
A24: 1.02.01.001 | B24: Valores Mobiliarios | C24: 6 | D24: N | H24: 4
A25: 1.02.01.002 | B25: Títulos Públicos | C25: 7 | D25: N | H25: 4
A26: 1.02.01.003 | B26: Fondo común de inversión | C26: 1977 | D26: N | E26: 3 | H26: 4
A27: 1.02.01.004 | B27: Plazos Fijos | C27: 8 | D27: N | E27: 3 | H27: 4
A28: 1.02.01.005 | B28: Intereses Plazo Fijo No Devengados | C28: 9 | D28: N | H28: 4
A29: 1.02.01.006 | B29: Plazo fijo en dólares | C29: 1973 | D29: N | E29: 3 | F29: 2 | H29: 4
A30: 1.02.02 | B30: INVERSIONES PERMANENTES | H30: 3
A31: 1.02.02.001 | B31: Inversiones en otras empresas | C31: 1905 | D31: N | H31: 4
A32: 1.02.02.002 | B32: Inversiones en Inmuebles | C32: 56 | D32: N | H32: 4
A33: 1.02.02.003 | B33: Am.Acum. Inm.p/ inversión | C33: 2097 | D33: N | H33: 4
A34: 1.02.02.004 | B34: Aportes Mejora Torres SP--MEJORA | C34: 3877 | D34: N | E34: 4 | H34: 4
A35: 1.02.02.005 | B35: Inversión de socios - Torres SP SRL | C35: 3878 | D35: N | H35: 4
A36: 1.02.02.006 | B36: Aportes DOLARES (M) Torres SP | C36: 3882 | D36: N | E36: 4 | H36: 4
A37: 1.02.02.007 | B37: Inversion General Paz 253 | C37: 3841 | D37: N | H37: 4
A38: 1.02.02.008 | B38: Inversión en Torres SP SRL | C38: 3875 | D38: N | H38: 4
A39: 1.02.02.009 | B39: Socio por cuenta prestamo Torres SP SRL | C39: 3876 | D39: N | E39: 4 | H39: 4
A40: 1.02.03 | B40: OTRAS INVERSIONES | H40: 3
...

Sheet PLAN DE CUENTAS VIEJO
A1: PLAN DE CUENTAS VIEJO | H1: ANALISIS LUCIA | O1: CUENTA PLAN DE CUENTAS NUEVO
A2: Codigo | B2: Nombre de cuenta | C2: Imput | D2: Resultado? | E2: Tipo Sub Cta | F2: Moneda | H2: SALDO?? | I2: Mov 2023? | J2: Observacion | K2: Nivel | L2: TIPO | M2: Caracteres | O2: Codigo OK | P2: Nombre de cuenta OK | Q2: Imput OK | R2: Resultado OK | S2: Tipo Sub Cta OK | T2: Moneda OK | V2: Nivel
A3: 1 | B3: ACTIVO | D3: N | I3: =+IFERROR(VLOOKUP(C3,'Mov 2023 hasta ahora '!$C$2:$D$314,2,FALSE),"NO") -> NO | J3: ok | K3: 1 | L3: PATRIMONIAL | M3: 1
A4: 1.01 | B4: CASA CENTRAL | D4: N | I4: =+IFERROR(VLOOKUP(C4,'Mov 2023 hasta ahora '!$C$2:$D$314,2,FALSE),"NO") -> NO | J4: Eliminar | K4: 2 | L4: PATRIMONIAL | M4: 4
A5: 1.01.01 | B5: DISPONIBILIDADES | D5: N | I5: =+IFERROR(VLOOKUP(C5,'Mov 2023 hasta ahora '!$C$2:$D$314,2,FALSE),"NO") -> NO | J5: ok | K5: 3 | L5: PATRIMONIAL | M5: 10
A6: 1.01.01.01 | B6: CAJAS | D6: N | I6: =+IFERROR(VLOOKUP(C6,'Mov 2023 hasta ahora '!$C$2:$D$314,2,FALSE),"NO") -> NO | J6: ok | K6: 4 | L6: PATRIMONIAL | M6: 14
A7: 1.01.01.01.01 | B7: Caja | C7: 1 | D7: N | I7: =+IFERROR(VLOOKUP(C7,'Mov 2023 hasta ahora '!$C$2:$D$314,2,FALSE),"NO") -> 13968 | J7: ok | K7: 5 | L7: PATRIMONIAL | M7: 18 | O7: 1.01.01.001 | P7: Caja | Q7: 1 | R7: N
A8: 1.01.01.01.02 | B8: Caja M. Extr. U$S | C8: 2 | D8: N | F8: 2 | I8: =+IFERROR(VLOOKUP(C8,'Mov 2023 hasta ahora '!$C$2:$D$314,2,FALSE),"NO") -> 849 | J8: ok | K8: 5 | L8: PATRIMONIAL | M8: 18 | O8: 1.01.01.002 | P8: Caja M. Extr. U$S | Q8: 2 | R8: N | T8: =+F8 -> 2
A9: 1.01.01.01.03 | B9: Fondo Fijo | C9: 3 | D9: N | I9: =+IFERROR(VLOOKUP(C9,'Mov 2023 hasta ahora '!$C$2:$D$314,2,FALSE),"NO") -> 668 | J9: ok | K9: 5 | L9: PATRIMONIAL | M9: 18 | O9: 1.01.01.003 | P9: Fondo Fijo | Q9: 3 | R9: N
A10: 1.01.01.01.04 | B10: Caja Mg | C10: 146 | D10: N | E10: 3 | H10: NO | I10: =+IFERROR(VLOOKUP(C10,'Mov 2023 hasta ahora '!$C$2:$D$314,2,FALSE),"NO") -> NO | J10: Eliminar | K10: 5 | L10: PATRIMONIAL | M10: 18 | O10: 1.02.01.004 | P10: Plazos Fijos | Q10: 8
A11: 1.01.01.01.05 | B11: Caja Central | C11: 152 | D11: N | I11: =+IFERROR(VLOOKUP(C11,'Mov 2023 hasta ahora '!$C$2:$D$314,2,FALSE),"NO") -> 1087 | J11: ok | K11: 5 | L11: PATRIMONIAL | M11: 18 | O11: 1.01.01.004 | P11: Caja Central | Q11: 152 | R11: N
A12: 1.01.01.01.06 | B12: Mon Extranjera Maguitur | C12: 338 | D12: N | F12: 2 | H12: NO | I12: =+IFERROR(VLOOKUP(C12,'Mov 2023 hasta ahora '!$C$2:$D$314,2,FALSE),"NO") -> NO | J12: Eliminar | K12: 5 | L12: PATRIMONIAL | M12: 18 | O12: 1.01.01.002 | P12: Caja M. Extr. U$S | Q12: 2 | T12: 2
A13: 1.01.01.01.07 | B13: Caja de Seg Efec-Citibank | C13: 339 | D13: N | H13: NO | I13: =+IFERROR(VLOOKUP(C13,'Mov 2023 hasta ahora '!$C$2:$D$314,2,FALSE),"NO") -> NO | J13: Eliminar | K13: 5 | L13: PATRIMONIAL | M13: 18 | O13: 1.01.01.007 | P13: Diferencia de Caja | Q13: 1736
A14: 1.01.01.01.08 | B14: Caja de Seg M Extr.-U$S-Citibank | C14: 340 | D14: N | F14: 2 | H14: NO | I14: =+IFERROR(VLOOKUP(C14,'Mov 2023 hasta ahora '!$C$2:$D$314,2,FALSE),"NO") -> NO | J14: Eliminar | K14: 5 | L14: PATRIMONIAL | M14: 18 | O14: 1.01.01.002 | P14: Caja M. Extr. U$S | Q14: 2 | T14: 2
A15: 1.01.01.01.09 | B15: Caja Maguitur (no Usar Todavia) | C15: 1741 | D15: N | E15: 3 | H15: NO | I15: =+IFERROR(VLOOKUP(C15,'Mov 2023 hasta ahora '!$C$2:$D$314,2,FALSE),"NO") -> NO | J15: Eliminar | K15: 5 | L15: PATRIMONIAL | M15: 18 | O15: 1.02.01.004 | P15: Plazos Fijos | Q15: 8
A16: 1.01.01.01.10 | B16: Caja de seg.efect.-Bco.Rio MaipÃ¹ | C16: 1974 | D16: N | I16: =+IFERROR(VLOOKUP(C16,'Mov 2023 hasta ahora '!$C$2:$D$314,2,FALSE),"NO") -> 4 | J16: ok | K16: 5 | L16: PATRIMONIAL | M16: 18 | O16: 1.01.01.005 | P16: Caja de seg.efect.-Bco.Rio Maipú | Q16: 1974 | R16: N
A17: 1.01.01.01.11 | B17: Caja seguridad efectivo-Bco.Rio-Tribunales | C17: 1975 | D17: N | H17: NO | I17: =+IFERROR(VLOOKUP(C17,'Mov 2023 hasta ahora '!$C$2:$D$314,2,FALSE),"NO") -> NO | J17: Eliminar | K17: 5 | L17: PATRIMONIAL | M17: 18 | O17: 1.01.01.007 | P17: Diferencia de Caja | Q17: 1736
A18: 1.01.01.01.12 | B18: Caja M. Extranj.- Euros | C18: 2122 | D18: N | F18: 3 | H18: NO | I18: =+IFERROR(VLOOKUP(C18,'Mov 2023 hasta ahora '!$C$2:$D$314,2,FALSE),"NO") -> NO | J18: Eliminar | K18: 5 | L18: PATRIMONIAL | M18: 18 | O18: 1.01.01.013 | P18: Caja M. Extr. Euros | Q18: 2122
A19: 1.01.01.01.13 | B19: Caja Seg M.Extr.-U$S-Bco.Rio Tribunales | C19: 2123 | D19: N | F19: 2 | H19: NO | I19: =+IFERROR(VLOOKUP(C19,'Mov 2023 hasta ahora '!$C$2:$D$314,2,FALSE),"NO") -> NO | J19: Eliminar | K19: 5 | L19: PATRIMONIAL | M19: 18 | O19: 1.01.01.002 | P19: Caja M. Extr. U$S | Q19: 2 | T19: 2
A20: 1.01.01.01.14 | B20: Caja Seg-U$S-Nro 48-Bco Santander-WCL | C20: 2124 | D20: N | F20: 2 | I20: =+IFERROR(VLOOKUP(C20,'Mov 2023 hasta ahora '!$C$2:$D$314,2,FALSE),"NO") -> 175 | J20: ok | K20: 5 | L20: PATRIMONIAL | M20: 18 | O20: 1.01.01.006 | P20: Caja Seg-U$S-Nro 48-Bco Santander-WCL | Q20: 2124 | R20: N | T20: =+F20 -> 2
A21: 1.01.01.01.15 | B21: Caja M.Extr-Euros-Citibank | C21: 2125 | D21: N | F21: 3 | H21: NO | I21: =+IFERROR(VLOOKUP(C21,'Mov 2023 hasta ahora '!$C$2:$D$314,2,FALSE),"NO") -> NO | J21: Eliminar | K21: 5 | L21: PATRIMONIAL | M21: 18 | O21: 1.01.01.013 | P21: Caja M. Extr. Euros | Q21: 2122
A22: 1.01.01.01.16 | B22: Caja Seg M.Extr.-Euros-Tribunales-Bco.Rio | C22: 2126 | D22: N | F22: 3 | H22: NO | I22: =+IFERROR(VLOOKUP(C22,'Mov 2023 hasta ahora '!$C$2:$D$314,2,FALSE),"NO") -> NO | J22: Eliminar | K22: 5 | L22: PATRIMONIAL | M22: 18 | O22: 1.01.01.013 | P22: Caja M. Extr. Euros | Q22: 2122
A23: 1.01.01.01.17 | B23: Caja Seg.M.Extr.- Euros-Maipu-Bco.Rio | C23: 2127 | D23: N | F23: 3 | H23: NO | I23: =+IFERROR(VLOOKUP(C23,'Mov 2023 hasta ahora '!$C$2:$D$314,2,FALSE),"NO") -> NO | J23: Eliminar | K23: 5 | L23: PATRIMONIAL | M23: 18 | O23: 1.01.01.013 | P23: Caja M. Extr. Euros | Q23: 2122
A24: 1.01.01.01.18 | B24: Caja de seg.Efect.-Anta La Rinconada | C24: 2987 | D24: N | H24: NO | I24: =+IFERROR(VLOOKUP(C24,'Mov 2023 hasta ahora '!$C$2:$D$314,2,FALSE),"NO") -> NO | J24: Eliminar | K24: 5 | L24: PATRIMONIAL | M24: 18 | O24: 1.01.01.007 | P24: Diferencia de Caja | Q24: 1736
A25: 1.01.01.01.19 | B25: Caja de Segur.-Dolares-Anta La Rinconada | C25: 2988 | D25: N | H25: NO | I25: =+IFERROR(VLOOKUP(C25,'Mov 2023 hasta ahora '!$C$2:$D$314,2,FALSE),"NO") -> NO | J25: Eliminar | K25: 5 | L25: PATRIMONIAL | M25: 18 | O25: 1.01.01.007 | P25: Diferencia de Caja | Q25: 1736
A26: 1.01.01.01.20 | B26: Diferencia de Caja | C26: 1736 | D26: N | I26: =+IFERROR(VLOOKUP(C26,'Mov 2023 hasta ahora '!$C$2:$D$314,2,FALSE),"NO") -> 83 | J26: ok | K26: 5 | L26: PATRIMONIAL | M26: 18 | O26: 1.01.01.007 | P26: Diferencia de Caja | Q26: 1736 | R26: N
A27: 1.01.01.01.21 | B27: Diferencia Caja Maguitur | C27: 1739 | D27: N | H27: NO | I27: =+IFERROR(VLOOKUP(C27,'Mov 2023 hasta ahora '!$C$2:$D$314,2,FALSE),"NO") -> NO | J27: Eliminar | K27: 5 | L27: PATRIMONIAL | M27: 18 | O27: 1.01.01.007 | P27: Diferencia de Caja | Q27: 1736
A28: 1.01.01.01.22 | B28: Diferencia Moneda Extranjera | C28: 1740 | D28: N | F28: 2 | I28: =+IFERROR(VLOOKUP(C28,'Mov 2023 hasta ahora '!$C$2:$D$314,2,FALSE),"NO") -> 13 | J28: ok | K28: 5 | L28: PATRIMONIAL | M28: 18 | O28: 1.01.01.008 | P28: Diferencia Moneda Extranjera | Q28: 1740 | R28: N | T28: =+F28 -> 2
A29: 1.01.01.01.23 | B29: Caja de seg.MaipÃ Efect. PCIW-3/4 | C29: 2694 | D29: N | H29: NO | I29: =+IFERROR(VLOOKUP(C29,'Mov 2023 hasta ahora '!$C$2:$D$314,2,FALSE),"NO") -> NO | J29: Eliminar | K29: 5 | L29: PATRIMONIAL | M29: 18 | O29: 1.01.01.007 | P29: Diferencia de Caja | Q29: 1736
A30: 1.01.01.01.24 | B30: Caja seg. Maipú U$S PCIW 3/4 | C30: 2695 | D30: N | F30: 2 | H30: NO | I30: =+IFERROR(VLOOKUP(C30,'Mov 2023 hasta ahora '!$C$2:$D$314,2,FALSE),"NO") -> NO | J30: Eliminar | K30: 5 | L30: PATRIMONIAL | M30: 18 | O30: 1.01.01.002 | P30: Caja M. Extr. U$S | Q30: 2 | T30: 2
A31: 1.01.01.01.25 | B31: Caja seg. Maipú Euros PCIW 3/4 | C31: 2696 | D31: N | F31: 3 | H31: NO | I31: =+IFERROR(VLOOKUP(C31,'Mov 2023 hasta ahora '!$C$2:$D$314,2,FALSE),"NO") -> NO | J31: Eliminar | K31: 5 | L31: PATRIMONIAL | M31: 18 | O31: 1.01.01.013 | P31: Caja M. Extr. Euros | Q31: 2122
A32: 1.01.01.01.26 | B32: Caja DroguerÃ­a | C32: 3435 | D32: N | H32: NO | I32: =+IFERROR(VLOOKUP(C32,'Mov 2023 hasta ahora '!$C$2:$D$314,2,FALSE),"NO") -> NO | J32: Eliminar | K32: 5 | L32: PATRIMONIAL | M32: 18 | O32: 1.01.01.007 | P32: Diferencia de Caja | Q32: 1736
A33: 1.01.01.01.28 | B33: Caja Buffo | C33: 3436 | D33: N | H33: NO | I33: =+IFERROR(VLOOKUP(C33,'Mov 2023 hasta ahora '!$C$2:$D$314,2,FALSE),"NO") -> 2 | J33: Eliminar | K33: 5 | L33: PATRIMONIAL | M33: 18 | O33: 1.01.01.007 | P33: Diferencia de Caja | Q33: 1736
A34: 1.01.01.01.29 | B34: Caja Seg Solano Vera - Bco Rio Efect | C34: 3440 | H34: NO | I34: =+IFERROR(VLOOKUP(C34,'Mov 2023 hasta ahora '!$C$2:$D$314,2,FALSE),"NO") -> NO | J34: Eliminar | K34: 5 | L34: PATRIMONIAL | M34: 18 | O34: 1.01.01.007 | P34: Diferencia de Caja | Q34: 1736
A35: 1.01.01.01.30 | B35: Caja Seg Efectivo Buffo - Bco Rio | C35: 3462 | H35: NO | I35: =+IFERROR(VLOOKUP(C35,'Mov 2023 hasta ahora '!$C$2:$D$314,2,FALSE),"NO") -> NO | J35: Eliminar | K35: 5 | L35: PATRIMONIAL | M35: 18 | O35: 1.01.01.007 | P35: Diferencia de Caja | Q35: 1736
A36: 1.01.01.01.31 | B36: Caja Compensacion | C36: 3600 | I36: =+IFERROR(VLOOKUP(C36,'Mov 2023 hasta ahora '!$C$2:$D$314,2,FALSE),"NO") -> 2160 | J36: ok | K36: 5 | L36: PATRIMONIAL | M36: 18 | O36: 1.01.01.009 | P36: Caja Compensación | Q36: 3600 | R36: N
A37: 1.01.01.01.32 | B37: Caja Fiduciario Fid.San Pablo Este | C37: 3844 | D37: N | I37: =+IFERROR(VLOOKUP(C37,'Mov 2023 hasta ahora '!$C$2:$D$314,2,FALSE),"NO") -> 74 | J37: ok | K37: 5 | L37: PATRIMONIAL | M37: 18 | O37: 1.01.01.010 | P37: Caja Fiduciario Fid.San Pablo Este | Q37: 3844 | R37: N
A38: 1.01.01.01.33 | B38: Caja Administración | C38: 3870 | I38: =+IFERROR(VLOOKUP(C38,'Mov 2023 hasta ahora '!$C$2:$D$314,2,FALSE),"NO") -> 2007 | J38: ok | K38: 5 | L38: PATRIMONIAL | M38: 18 | O38: 1.01.01.011 | P38: Caja Administración | Q38: 3870 | R38: N
A39: 1.01.01.01.34 | B39: Caja Seg U$S-Nro 4-Bco Francés-Torres SP SRL | C39: 3874 | D39: N | F39: 2 | I39: =+IFERROR(VLOOKUP(C39,'Mov 2023 hasta ahora '!$C$2:$D$314,2,FALSE),"NO") -> 23 | J39: ok | K39: 5 | L39: PATRIMONIAL | M39: 18 | O39: 1.01.01.012 | P39: Caja Seg U$S-Nro 4-Bco Francés-Torres SP SRL | Q39: 3874 | R39: N | T39: =+F39 -> 2
A40: 1.01.01.02 | B40: BANCOS | D40: N | I40: =+IFERROR(VLOOKUP(C40,'Mov 2023 hasta ahora '!$C$2:$D$314,2,FALSE),"NO") -> NO | J40: ok | K40: 4 | L40: PATRIMONIAL | M40: 14
...

Sheet Mov 2023 hasta ahora 
A1: CODCTA | B1: DESCRIP | C1: NROCTA | D1: COUNT(*)
A2: 201020103 | B2: ART a pagar | C2: 45 | D2: 52
A3: 201020105 | B3: UOCRA a pagar | C3: 47 | D3: 54
A4: 301010101 | B4: Capital Social | C4: 134 | D4: 2
A5: 301010103 | B5: Aportes Irrevocables | C5: 136 | D5: 226
A6: 4331035660102 | B6: Alq x cta de 3 -Maipu 605-Alquileres | C6: 2283 | D6: 1386
A7: 101040122 | B7: Ingr. Brutos Saldo a Favor | C7: 1888 | D7: 266
A8: 5010107230001 | B8: Revestimiento-Revestimiento-Materiales | C8: 537 | D8: 2
A9: 5044115600067 | B9: Gs a Distribuir-Vs M Obra-Impresos y Util | C9: 1825 | D9: 7
A10: 101040230 | B10: Serv.contratados a cobrar | C10: 1980 | D10: 138
A11: 5918182860070 | B11: Gs administra-Gs Escrituras | C11: 1254 | D11: 5
A12: 5918182890117 | B12: Imp y Tasas-TACIS - TEM | C12: 1270 | D12: 54
A13: 5918182890126 | B13: Imp y Tasas-Otros Imp y Tas | C13: 1275 | D13: 360
... A314: 4217730010005 | B314: Gcia Batia Loteo Prados del Libertador Sofia L II | C314: 3849 | D314: 8
